<?xml version="1.0"?>
<robot name="simple_example">
  <!--Link #1-->
  <link name="base_link">
    <inertial>
        <mass value="20" />
        <inertia ixx="0.4" ixy="0.0" ixz="0.0" iyy="0.4" iyz="0.0" izz="0.2"/>
    </inertial>
    <collision>
      <origin xyz="-0.11 0 0.251" rpy="1.570796327 0 1.570796327"/>
      <geometry>
        <mesh filename="package://truck_description/urdf/chassis/caben.STL" scale="0.000105 0.000098 0.000075"/>
      </geometry>
    </collision>
    <visual>
      <origin xyz="-0.11 0 0.251" rpy="1.570796327 0 1.570796327"/>
      <geometry>
        <mesh filename="package://truck_description/urdf/chassis/caben.STL" scale="0.000105 0.000098 0.000075"/>
      </geometry>
    </visual>
  </link>

  <link name="ban_link">
    <inertial>
        <mass value="20" />
        <inertia ixx="0.2" ixy="0.0" ixz="0.0" iyy="0.4" iyz="0.0" izz="0.2"/>
    </inertial>
    <collision>
      <origin xyz="0.272 0 -0.094" rpy="1.570796327 0 1.570796327"/>
      <geometry>
        <mesh filename="package://truck_description/urdf/chassis/ban.STL" scale="0.000105 0.000098 0.000075"/>
      </geometry>
    </collision>
    <visual>
      <origin xyz="0.272 0 -0.094" rpy="1.570796327 0 1.570796327"/>
      <geometry>
        <mesh filename="package://truck_description/urdf/chassis/ban.STL" scale="0.000105 0.000098 0.000075"/>
      </geometry>
    </visual>
  </link>

  <!--joint-->
  <joint name="base_to_ban_joint" type="continuous">
    <parent link="base_link"/>
    <child link="ban_link"/>
    <axis xyz="0 1 0"/>
    <origin xyz="-0.605 0.0 0.387" rpy="0.0 0.0 0.0"/> 
  </joint>


<link name="base_footprint" />
  <joint name="base_footprint_joint" type="fixed">
    <parent link="base_footprint"/>
    <child link="base_link"/>
    <axis xyz="0 0 0"/>
    <origin xyz="0 0.0 0" rpy="0.0 0.0 0.0"/> 
  </joint>
  <!--                GAZEBO RELATED PART                             -->

  <!-- ROS Control plugin for Gazebo. This allows Gazebo and Ros to to be connected,
       and for ros to control the model in the gazebo visualization -->
  <gazebo>
    <plugin name="gazebo_ros_control" filename="libgazebo_ros_control.so">
	  <!--this is the namespace in the yaml file-->
      <robotNamespace>/simple_model</robotNamespace>
      <!--The two lines below came from: https://answers.ros.org/question/292444/gazebo_ros_control-plugin-gazeboroscontrolplugin-missing-legacymodens-defaultrobothwsim/-->
      <robotSimType>gazebo_ros_control/DefaultRobotHWSim</robotSimType>
      <legacyModeNS>true</legacyModeNS>
    </plugin>
  </gazebo>


  <!-- transmission is the ability to define the ros controller used to control the joint. -->
  <transmission name="base_to_second_trans">
    <type>transmission_interface/SimpleTransmission</type>
    <actuator name="motor1">
      <mechanicalReduction>1</mechanicalReduction>
    </actuator>
    <joint name="base_to_ban_joint">
      <!--lets use a postion type interface, which is a mechanism for ros_control
          to communicate with hardware. See: https://wiki.ros.org/ros_control-->
      <!--hardwareInterface>hardware_interface/PositionJointInterface</hardwareInterface-->
      <hardwareInterface>hardware_interface/VelocityJointInterface</hardwareInterface>
    </joint>
  </transmission>


  <!-- ########################################" fr_steer_link ########################################## -->
  <link name="fr_steer_link">
    <inertial>
        <mass value="2" />
        <inertia ixx="0.2" ixy="0.0" ixz="0.0" iyy="0.4" iyz="0.0" izz="0.2"/>
    </inertial>
    <collision>
      <geometry>
        <cylinder radius="0.05" length="0.24" />
      </geometry>
        </collision>
    <visual>
      <origin xyz="0 0 0" rpy="1.570796327 0 1.570796327"/>
      <geometry>
        <box size="0.05 0.05 0.05"/>
      </geometry>
    </visual>
  </link>
    <gazebo reference="fr_steer_link">
      <material>Gazebo/Blue</material>
    </gazebo>
  <!--joint-->
  <joint name="base_to_fr_steer_joint" type="continuous">
    <parent link="base_link"/>
    <child link="fr_steer_link"/>
    <axis xyz="0 0 1"/>
    <origin xyz="-0.135 0.22 0.15" rpy="0.0 0.0 0.0"/> 
  </joint>
  <transmission name="base_to_fr_steer_trans">
    <type>transmission_interface/SimpleTransmission</type>
    <actuator name="motor1">
      <mechanicalReduction>1</mechanicalReduction>
    </actuator>
    <joint name="base_to_fr_steer_joint">
      <hardwareInterface>hardware_interface/VelocityJointInterface</hardwareInterface>
    </joint>
  </transmission>

  <!-- ########################################" fl_steer_link ########################################## -->
  <link name="fl_steer_link">
    <inertial>
        <mass value="2" />
        <inertia ixx="0.2" ixy="0.0" ixz="0.0" iyy="0.4" iyz="0.0" izz="0.2"/>
    </inertial>
    <collision>
      <geometry>
        <cylinder radius="0.005" length="0.0004" />
      </geometry>
        </collision>
    <visual>
      <origin xyz="0 0 0" rpy="1.570796327 0 1.570796327"/>
      <geometry>
        <box size="0.05 0.05 0.05"/>
      </geometry>
    </visual>
  </link>
    <gazebo reference="fl_steer_link">
      <material>Gazebo/Blue</material>
    </gazebo>

  <!--joint-->
  <joint name="base_to_fl_steer_joint" type="continuous">
    <parent link="base_link"/>
    <child link="fl_steer_link"/>
    <axis xyz="0 0 1"/>
    <origin xyz="-0.135 -0.22 0.15" rpy="0.0 0.0 0.0"/> 
  </joint>

  <transmission name="base_to_fl_steer_trans">
    <type>transmission_interface/SimpleTransmission</type>
    <actuator name="motor1">
      <mechanicalReduction>1</mechanicalReduction>
    </actuator>
    <joint name="base_to_fl_steer_joint">
      <hardwareInterface>hardware_interface/VelocityJointInterface</hardwareInterface>
    </joint>
  </transmission>
<!--%%%%%%%%%%%%%%%%%%%%%%%%%%%%%%%%%%%%%%%%%%%%%%%%%%%%%% fr_wheel_link %%%%%%%%%%%%%%%%%%%%%%%%%%%%%%%%%%%%%%%%%%%%%%%%%%%%%%%%%%%-->
  <link name="fr_wheel_link">
    <inertial>
        <mass value="2" />
        <inertia ixx="0.2" ixy="0.0" ixz="0.0" iyy="0.4" iyz="0.0" izz="0.2"/>
    </inertial>
    <collision>
      <origin xyz="0 0 0" rpy="1.57 0 0"/>
      <geometry>
        <cylinder radius=".15" length="0.04" />
      </geometry>
    </collision>
    <visual>
      <origin xyz="0 0 0" rpy="0 0 0"/>
      <geometry>
        <mesh filename="package://truck_description/urdf/chassis/wheel_husky.dae" scale="0.8 1.2 0.8"/>
      </geometry>
    </visual>
  </link>

    <gazebo reference="fr_wheel_link">
      <material>Gazebo/FlatBlack</material>
    </gazebo>

  <joint name="fr_wheel_joint" type="continuous">
    <parent link="fr_steer_link"/>
    <child link="fr_wheel_link"/>
    <axis xyz="0 1 0"/>
    <origin xyz="0 0.05 0" rpy="0.0 0.0 0.0"/> 
  </joint>



<!-- %%%%%%%%%%%%%%%%%%%%%%%%%%%%%%%%%%%%%%%%%%%%%%%%%%%%%%%%%%% fl_wheel_link %%%%%%%%%%%%%%%%%%%%%%%%%%%%%%%%%%%%%%%%%%%%%%%%%%%%%%%%-->
  <link name="fl_wheel_link">
    <inertial>
        <mass value="2" />
        <inertia ixx="0.2" ixy="0.0" ixz="0.0" iyy="0.4" iyz="0.0" izz="0.2"/>
    </inertial>
    <collision>
      <origin xyz="0 0 0" rpy="1.57 0 0"/>
      <geometry>
        <cylinder radius=".15" length="0.04" />
      </geometry>
    </collision>
    <visual>
      <origin xyz="0 0 0" rpy="0 0 0"/>
      <geometry>
        <mesh filename="package://truck_description/urdf/chassis/wheel_husky.dae" scale="0.8 1.2 0.8"/>
      </geometry>
    </visual>
  </link>

    <gazebo reference="fl_wheel_link">
      <material>Gazebo/FlatBlack</material>
    </gazebo>

  <joint name="fl_wheel_joint" type="continuous">
    <parent link="fl_steer_link"/>
    <child link="fl_wheel_link"/>
    <axis xyz="0 1 0"/>
    <origin xyz="0 -0.05 0" rpy="0.0 0.0 0.0"/> 
  </joint>



  <!-- ########################################" rfl_steer_link ########################################## -->
  <link name="rfl_steer_link">                   <!--   rear reight_left steer_link  axle-->
    <inertial>
        <mass value="2" />
        <inertia ixx="0.2" ixy="0.0" ixz="0.0" iyy="0.4" iyz="0.0" izz="0.2"/>
    </inertial>
    <collision>
      <geometry>
        <cylinder radius="0.005" length="0.0004" />
      </geometry>
    </collision>
    <visual>
      <origin xyz="0 0 0" rpy="1.570796327 0 1.570796327"/>
      <geometry>
        <box size="0.4 0.02 0.02"/>
      </geometry>
    </visual>
  </link>
    <gazebo reference="rfl_steer_link">
      <material>Gazebo/Blue</material>
    </gazebo>

  <!--joint-->
  <joint name="rfl_steer_joint" type="fixed">
    <parent link="base_link"/>
    <child link="rfl_steer_link"/>
    <origin xyz="-0.58 0 0.137" rpy="0.0 0.0 0.0"/> 
  </joint>


<!-- %%%%%%%%%%%%%%%%%%%%%%%%%%%%%%%%%%%%%%%%%%%%%%%%%%%%%%%%%%% rl_wheel_link %%%%%%%%%%%%%%%%%%%%%%%%%%%%%%%%%%%%%%%%%%%%%%%%%%%%%%%%-->
  <link name="rl_wheel_link">
    <inertial>
        <mass value="2" />
        <inertia ixx="0.2" ixy="0.0" ixz="0.0" iyy="0.4" iyz="0.0" izz="0.2"/>
    </inertial>
    <collision>
      <origin xyz="0 0 0" rpy="1.57 0 0"/>
      <geometry>
        <cylinder radius=".145" length="0.04" />
      </geometry>
   </collision>
    <visual>
      <origin xyz="0 0 0" rpy="0 0 0"/>
      <geometry>
        <mesh filename="package://truck_description/urdf/chassis/wheel_husky.dae" scale="0.8 2 0.8"/>
      </geometry>
    </visual>
  </link>

    <gazebo reference="rl_wheel_link">
      <material>Gazebo/FlatBlack</material>
    </gazebo>

	<joint name="rl_wheel_joint" type="continuous">
		<parent link="rfl_steer_link"/>
		<child link="rl_wheel_link"/>
		<axis xyz="0 1 0"/>
		<origin xyz="0 0.22 0" rpy="0 0 0" />
	</joint>

<!-- %%%%%%%%%%%%%%%%%%%%%%%%%%%%%%%%%%%%%%%%%%%%%%%%%%%%%%%%%%% rl_wheel_link %%%%%%%%%%%%%%%%%%%%%%%%%%%%%%%%%%%%%%%%%%%%%%%%%%%%%%%%-->
  <link name="rr_wheel_link">
    <inertial>
        <mass value="2" />
        <inertia ixx="0.2" ixy="0.0" ixz="0.0" iyy="0.4" iyz="0.0" izz="0.2"/>
    </inertial>
    <collision>
      <origin xyz="0 0 0" rpy="1.57 0 0"/>
      <geometry>
        <cylinder radius=".145" length="0.04" />
      </geometry>
    </collision>
    <visual>
      <origin xyz="0 0 0" rpy="0 0 0"/>
      <geometry>
        <mesh filename="package://truck_description/urdf/chassis/wheel_husky.dae" scale="0.8 2 0.8"/>
      </geometry>
    </visual>
  </link>

    <gazebo reference="rr_wheel_link">
      <material>Gazebo/FlatBlack</material>
    </gazebo>

	<joint name="rr_wheel_joint" type="continuous">
		<parent link="rfl_steer_link"/>
		<child link="rr_wheel_link"/>
		<axis xyz="0 1 0"/>
		<origin xyz="0 -0.22 0" rpy="0 0 0" />
	</joint>

<!-- ==========================  SENSORS laser scan ================================== -->
	<link name="hokuyo_link">
        <visual>
			<origin rpy="0 0 0" xyz="0 .001 0"/>
            <geometry>
                <box size="0.07 0.05 0.05"/>
            </geometry>
			<material name="blue"/>
        </visual>
    </link>

	<joint name="hokuyo_joint" type="fixed">
		<parent link="base_link"/>
		<child link="hokuyo_link"/>
		<origin xyz="0.13 0 0.15" rpy="0 0 0" />
	</joint>

	<gazebo reference="hokuyo_link">
    <material>Gazebo/Blue</material>
	    <sensor name="head_hokuyo_sensor" type="ray">
	      <pose>0.2 0 0 0 0 0</pose>
	      <visualize>true</visualize>
	      <update_rate>10</update_rate>
	      <ray>
	        <scan>
	          <horizontal>
	            <samples>720</samples>
	            <resolution>.05</resolution>
	            <min_angle>-1.570796</min_angle>
	            <max_angle>1.570796</max_angle>
	          </horizontal>
	        </scan>
	        <range>
	          <min>0.10</min>
	          <max>5.0</max>
	          <resolution>0.1</resolution>
	        </range>
	      </ray>
	      <plugin filename="libgazebo_ros_laser.so" name="gazebo_ros_head_hokuyo_controller">
	        <topicName>/scan</topicName>
	        <frameName>hokuyo_link</frameName>
	      </plugin>
	    </sensor>
  	</gazebo>

<!-- ==========================   sensor_imu   ================================== -->
<link name="imu_link">    
        <visual>
        <origin xyz="0 0 .035" rpy="0 0 0" />
            <geometry>
		        <box size = "0.01 0.01 0.015"/> 
		    </geometry>
        </visual>
    <collision>         
        <geometry>
            <box size = "0.01 0.01 0.01"/> 
        </geometry>
    </collision>     
    </link>

<joint name="imu_joint" type="fixed">
    <axis xyz="0 0 0"/>
    <origin xyz="0 0 -0.01" rpy="0 0 0" />
    <parent link="hokuyo_link"/>
    <child link="imu_link" />
</joint>

<gazebo>    
    <plugin name="imu_plugin" filename="libgazebo_ros_imu.so">
        <alwaysOn>true</alwaysOn>       
        <bodyName>imu_link</bodyName>
        <frameName>imu_link</frameName>
        <topicName>imu/data</topicName>
        <serviceName>imu_service</serviceName>
        <gaussianNoise>0.0</gaussianNoise>
        <updateRate>5.0</updateRate> 
    </plugin>
</gazebo>

<!-- ==========================   sensor_gps   ================================== -->
  <link name="gps_link">
    <visual>
      <origin xyz="0.0 0 0.0" rpy="0 0 3.14159"/>
      <geometry>
        <mesh filename="package://truck_description/meshes/GPS_garmin.stl" scale="0.00012 0.00012 0.0001"/>
      </geometry>
      <material name="black"/>
    </visual>
  </link>

  <joint name="gps_joint" type="fixed">
    <parent link="imu_link"/>
    <child link="gps_link"/>
    <origin xyz="0.0 0 0.03" rpy="0 0 0"/>
  </joint>

  <gazebo reference="gps_link">
    <material>Gazebo/Black</material>
    <gravity>1</gravity>
  </gazebo>

  <gazebo>

	  <plugin name="quadrotor_gps_sim" filename="libhector_gazebo_ros_gps.so">
		<updateRate>5.0</updateRate>
		<bodyName>base_link</bodyName>
		<topicName>gps/fix</topicName>
		<velocityTopicName>fix_velocity</velocityTopicName>
		<referenceLatitude>49.860246</referenceLatitude>
		<referenceLongitude>8.687077</referenceLongitude>
		<drift>5.0 5.0 5.0</drift>
		<gaussianNoise>0.01 0.01 0.01</gaussianNoise>
		<velocityDrift>0 0 0</velocityDrift>
		<velocityGaussianNoise>0.05 0.05 0.05</velocityGaussianNoise>
	  </plugin>
  </gazebo>

<!-- ==========================   Camera_sensor   ================================== -->
  <link name="camera_link">

    <visual>
      <origin xyz="0 0 0" rpy="0 0 0"/>
      <geometry>
          <box size="0.001 0.001 0.001"/>
      </geometry>
      <material name="red"/>
    </visual>
  </link>

  <joint name="camera_joint" type="fixed">
    <axis xyz="0 1 0" />
    <origin xyz="0.036 0 0.025" rpy="0 0 0" />
    <parent link="hokuyo_link"/>
    <child link="camera_link"/>
  </joint>

  <gazebo reference="camera_link">
    <sensor type="camera" name="camera1">
      <update_rate>5</update_rate>
      <camera name="head">
        <horizontal_fov>1.3962634</horizontal_fov>
        <image>
          <width>800</width>
          <height>800</height>
          <format>R8G8B8</format>
        </image>
        <clip>
          <near>0.02</near>
          <far>300</far>
        </clip>
        <noise>
          <type>gaussian</type>
          <mean>0.0</mean>
          <stddev>0.007</stddev>
        </noise>
      </camera>
      <plugin name="camera_controller" filename="libgazebo_ros_camera.so">
        <alwaysOn>true</alwaysOn>
        <updateRate>5.0</updateRate>
        <cameraName>rrbot/camera1</cameraName>
        <imageTopicName>image_raw</imageTopicName>
        <cameraInfoTopicName>camera_info</cameraInfoTopicName>
        <frameName>camera_link</frameName>
        <hackBaseline>0.07</hackBaseline>
        <distortionK1>0.0</distortionK1>
        <distortionK2>0.0</distortionK2>
        <distortionK3>0.0</distortionK3>
        <distortionT1>0.0</distortionT1>
        <distortionT2>0.0</distortionT2>
      </plugin>
    </sensor>
  </gazebo>  

<!-- ==========================   sensor_odom and control rear wheel velocity   ================================== -->

 <gazebo>
  
	  <plugin filename="libgazebo_ros_diff_drive.so" name="differential_drive_controller_front">
		<rosDebugLevel>Debug</rosDebugLevel>
		<publishWheelTF>false</publishWheelTF>
		<robotNamespace>/</robotNamespace>
		<publishTf>1</publishTf>
		<publishWheelJointState>false</publishWheelJointState>
		<alwaysOn>true</alwaysOn>
		<updateRate>5.0</updateRate>
		<leftJoint>rl_wheel_joint</leftJoint>
		<rightJoint>rr_wheel_joint</rightJoint>
		<broadcastTF>1</broadcastTF>
		<odometryFrame>odom</odometryFrame>
		<odometryTopic>odom</odometryTopic>
		<robotBaseFrame>base_footprint</robotBaseFrame>
	  </plugin>
</gazebo>
<!-- ==========================   colors   ================================== -->
  <gazebo reference="ban_link">
    <material>Gazebo/DarkYellow</material>
  </gazebo>
  <gazebo reference="base_link">
    <material>Gazebo/ZincYellow</material>
  </gazebo>
  <gazebo reference="camera_link">
    <material>Gazebo/Red</material>
  </gazebo>

</robot>
